<?xml version="1.0" ?>
<robot name="astribot_torso">
  <link name="astribot_torso_base">
    <inertial>
      <origin rpy="0 0 0" xyz="-0.062784 0.007017 0.035375"/>
      <mass value="39.24781"/>
      <inertia ixx="1.071997" ixy="0.015889" ixz="-0.058447" iyy="1.218431" iyz="-0.002015" izz="1.489411"/>
    </inertial>
    <collision>
      <origin xyz="0 0 -0.05" rpy="0 0 0"/>
      <geometry>
        <cylinder radius="0.3" length="0.1"/>
      </geometry>
    </collision>
  </link>
  <link name="astribot_torso_link_1">
    <inertial>
      <origin rpy="0 0 0" xyz="-0.17517 0.00014232 0.0026468"/>
      <mass value="6.5318"/>
      <inertia ixx="0.02706" ixy="-0.005257" ixz="0.00010866" iyy="0.1471" iyz="1.0342E-05" izz="0.13987"/>
    </inertial>
    <collision>
      <origin xyz="-0.15 0 0" rpy="0 1.57 0"/>
      <geometry>
        <cylinder radius="0.1" length="0.3"/>
      </geometry>
    </collision>
  </link>
  <joint name="astribot_torso_joint_1" type="revolute">
    <origin rpy="-1.5708 1.5708 0" xyz="0 0 0.12"/>
    <parent link="astribot_torso_base"/>
    <child link="astribot_torso_link_1"/>
    <axis xyz="0 0 1"/>
    <limit effort="100" lower="-0.04" upper="1.3" velocity="1.8"/>
  </joint>
  <link name="astribot_torso_link_2">
    <inertial>
      <origin rpy="0 0 0" xyz="-0.21778 0.026029 0.00073864"/>
      <mass value="6.2308"/>
      <inertia ixx="0.0085933" ixy="0.0011524" ixz="0.00035578" iyy="0.013017" iyz="-5.8175E-05" izz="0.018057"/>
    </inertial>
    <collision>
      <origin xyz="-0.15 0.03 0" rpy="0 1.57 -0.25"/>
      <geometry>
        <cylinder radius="0.1" length="0.3"/>
      </geometry>
    </collision>
  </link>
  <joint name="astribot_torso_joint_2" type="revolute">
    <origin rpy="0 0 0" xyz="-0.38 0 0"/>
    <parent link="astribot_torso_link_1"/>
    <child link="astribot_torso_link_2"/>
    <axis xyz="0 0 1"/>
    <limit effort="100" lower="-2.3" upper="0.06" velocity="1.8"/>
  </joint>
  <link name="astribot_torso_link_3">
    <inertial>
      <origin rpy="0 0 0" xyz="-0.062784 0.007017 0.035375"/>
      <mass value="0.49013"/>
      <inertia ixx="0.00022212" ixy="-2.6767E-07" ixz="4.3987E-07" iyy="0.00036522" iyz="3.8834E-07" izz="0.00038039"/>
    </inertial>
    <collision>
      <origin xyz="-0.18 0.01 0" rpy="0 1.57 0"/>
      <geometry>
        <cylinder radius="0.09" length="0.35"/>
      </geometry>
    </collision>
  </link>
  <joint name="astribot_torso_joint_3" type="revolute">
    <origin rpy="0 0 0" xyz="-0.390 0 0"/>
    <parent link="astribot_torso_link_2"/>
    <child link="astribot_torso_link_3"/>
    <axis xyz="0 0 1"/>
    <limit effort="100" lower="-0.4" upper="2.3" velocity="1.8"/>
  </joint>
  <link name="astribot_torso_link_4">
    <inertial>
      <origin rpy="0 0 0" xyz="0.00476227191516749 -4.56966810241128E-05 0.242912573510671"/>
      <mass value="3.55695635704638"/>
      <inertia ixx="0.0165768322563514" ixy="-9.94098112646385E-06" ixz="-0.000100011483384926" iyy="0.014904355097835" iyz="9.86752047032885E-07" izz="0.0110629318711333"/>
    </inertial>
  </link>
  <joint name="astribot_torso_joint_4" type="revolute">
    <origin rpy="1.5708 0 -1.5708" xyz="0 0 0"/>
    <parent link="astribot_torso_link_3"/>
    <child link="astribot_torso_link_4"/>
    <axis xyz="0 0 1"/>
    <limit effort="100" lower="-1.2" upper="1.2" velocity="1.8"/>
  </joint>
  <link name="astribot_torso_end_effector">
    <inertial>
      <origin rpy="0 0 0" xyz="0 0 0"/>
      <mass value="0"/>
      <inertia ixx="0" ixy="0" ixz="0" iyy="0" iyz="0" izz="0"/>
    </inertial>
  </link>
  <joint name="astribot_torso_end_effector_fixed_joint" type="fixed">
    <origin rpy="0.0 0.0 0.0" xyz="0 0 0.34475"/>
    <parent link="astribot_torso_link_4"/>
    <child link="astribot_torso_end_effector"/>
  </joint>
</robot>
