<?xml version="1.0"?>
<sdf version='1.7'>
  <model name='astribot_whole_body'>
    <link name="base"/>
    <!--joint between {parent} and link_0-->
    <joint name="base_joint" type="fixed">
      <child>astribot_torso_base</child>
      <parent>base</parent>
    </joint>
    <link name='astribot_torso_base'>
      <inertial>
        <pose>-0.062784 0.007017 0.035375 0 -0 0</pose>
        <mass>39.2478</mass>
        <inertia>
          <ixx>1.072</ixx>
          <ixy>0.015889</ixy>
          <ixz>-0.058447</ixz>
          <iyy>1.21843</iyy>
          <iyz>-0.002015</iyz>
          <izz>1.48941</izz>
        </inertia>
      </inertial>
      <collision name='astribot_torso_base_collision'>
        <pose>0 0 0.049 0 -0 0</pose>
        <geometry>
          <box>
            <size>0.56 0.56 0.29</size>
          </box>
        </geometry>
      </collision>
      <collision name='astribot_torso_base_collision_ground'>
        <pose>0 0 -0.106 0 -0 0</pose>
        <geometry>
          <cylinder>
            <length>0.001</length>
            <radius>0.8</radius>
          </cylinder>
        </geometry>
      </collision>
      <visual name='astribot_torso_base_visual'>
        <pose>0 0 0 0 -0 0</pose>
        <geometry>
          <mesh>
            <scale>1 1 1</scale>
            <uri>meshes/s1_torso/obj/astribot_torso_base_link.obj</uri>
          </mesh>
        </geometry>
      </visual>
    </link>
    <joint name='astribot_torso_joint_1' type='revolute'>
      <pose relative_to='astribot_torso_base'>0 0 0.12 1.57079 1.57079 -3.14159</pose>
      <parent>astribot_torso_base</parent>
      <child>astribot_torso_link_1</child>
      <axis>
        <xyz>0 0 1</xyz>
        <limit>
          <lower>-3.14</lower>
          <upper>3.14</upper>
          <effort>100</effort>
          <velocity>10</velocity>
          <drake:acceleration>0</drake:acceleration>
        </limit>
        <dynamics>
          <spring_reference>0</spring_reference>
          <spring_stiffness>0</spring_stiffness>
        </dynamics>
      </axis>
    </joint>
    <link name='astribot_torso_link_1'>
      <pose relative_to='astribot_torso_joint_1'>0 0 0 0 -0 0</pose>
      <inertial>
        <pose>-0.15249 0.000211 -0.003348 0 -0 0</pose>
        <mass>7.3766</mass>
        <inertia>
          <ixx>0.028834</ixx>
          <ixy>-0.0052759</ixy>
          <ixz>0.00010767</ixz>
          <iyy>0.1483</iyy>
          <iyz>1.1652e-05</iyz>
          <izz>0.14268</izz>
        </inertia>
      </inertial>
      <collision name='astribot_torso_link_1_collision'>
        <pose>0 0 0 0 -0 0</pose>
        <geometry>
          <mesh>
            <scale>1.2 1.2 1.2</scale>
            <uri>meshes/s1_torso/obj/astribot_torso_link_1_collision_mesh.obj</uri>
          </mesh>
        </geometry>
      </collision>
      <visual name='astribot_torso_link_1_visual'>
        <pose>0 0 0 0 -0 0</pose>
        <geometry>
          <mesh>
            <scale>1 1 1</scale>
            <uri>meshes/s1_torso/obj/astribot_torso_link_1.obj</uri>
          </mesh>
        </geometry>
      </visual>
    </link>
    <joint name='astribot_torso_joint_2' type='revolute'>
      <pose relative_to='astribot_torso_link_1'>-0.38 0 0 0 -0 0</pose>
      <parent>astribot_torso_link_1</parent>
      <child>astribot_torso_link_2</child>
      <axis>
        <xyz>0 0 1</xyz>
        <limit>
          <lower>-3.14</lower>
          <upper>3.14</upper>
          <effort>100</effort>
          <velocity>10</velocity>
          <drake:acceleration>0</drake:acceleration>
        </limit>
        <dynamics>
          <spring_reference>0</spring_reference>
          <spring_stiffness>0</spring_stiffness>
        </dynamics>
      </axis>
    </joint>
    <link name='astribot_torso_link_2'>
      <pose relative_to='astribot_torso_joint_2'>0 0 0 0 -0 0</pose>
      <inertial>
        <pose>-0.22214 0.028873 0.00059 0 -0 0</pose>
        <mass>5.6183</mass>
        <inertia>
          <ixx>0.0082545</ixx>
          <ixy>0.0011523</ixy>
          <ixz>0.00035614</ixz>
          <iyy>0.012677</iyy>
          <iyz>-5.8287e-05</iyz>
          <izz>0.017512</izz>
        </inertia>
      </inertial>
      <collision name='astribot_torso_link_2_collision'>
        <pose>0 0 0 0 -0 0</pose>
        <geometry>
          <mesh>
            <scale>1.2 1.2 1.2</scale>
            <uri>meshes/s1_torso/obj/astribot_torso_link_2_collision_mesh.obj</uri>
          </mesh>
        </geometry>
      </collision>
      <visual name='astribot_torso_link_2_visual'>
        <pose>0 0 0 0 -0 0</pose>
        <geometry>
          <mesh>
            <scale>1 1 1</scale>
            <uri>meshes/s1_torso/obj/astribot_torso_link_2.obj</uri>
          </mesh>
        </geometry>
      </visual>
    </link>
    <joint name='astribot_torso_joint_3' type='revolute'>
      <pose relative_to='astribot_torso_link_2'>-0.39 0 0 0 -0 0</pose>
      <parent>astribot_torso_link_2</parent>
      <child>astribot_torso_link_3</child>
      <axis>
        <xyz>0 0 1</xyz>
        <limit>
          <lower>-3.14</lower>
          <upper>3.14</upper>
          <effort>100</effort>
          <velocity>10</velocity>
          <drake:acceleration>0</drake:acceleration>
        </limit>
        <dynamics>
          <spring_reference>0</spring_reference>
          <spring_stiffness>0</spring_stiffness>
        </dynamics>
      </axis>
    </joint>
    <link name='astribot_torso_link_3'>
      <pose relative_to='astribot_torso_joint_3'>0 0 0 0 -0 0</pose>
      <inertial>
        <pose>-0.017519 0.000595 0.000258 0 -0 0</pose>
        <mass>0.49013</mass>
        <inertia>
          <ixx>0.00022212</ixx>
          <ixy>-2.6767e-07</ixy>
          <ixz>4.3987e-07</ixz>
          <iyy>0.00036522</iyy>
          <iyz>3.8834e-07</iyz>
          <izz>0.00038039</izz>
        </inertia>
      </inertial>
      <visual name='astribot_torso_link_3_visual'>
        <pose>0 0 0 0 -0 0</pose>
        <geometry>
          <mesh>
            <scale>1 1 1</scale>
            <uri>meshes/s1_torso/obj/astribot_torso_link_3.obj</uri>
          </mesh>
        </geometry>
      </visual>
    </link>
    <joint name='astribot_torso_joint_4' type='revolute'>
      <pose relative_to='astribot_torso_link_3'>0 0 0 1.5708 0 -1.5708</pose>
      <parent>astribot_torso_link_3</parent>
      <child>astribot_torso_link_4</child>
      <axis>
        <xyz>0 0 1</xyz>
        <limit>
          <lower>-3.14</lower>
          <upper>3.14</upper>
          <effort>100</effort>
          <velocity>10</velocity>
          <drake:acceleration>0</drake:acceleration>
        </limit>
        <dynamics>
          <spring_reference>0</spring_reference>
          <spring_stiffness>0</spring_stiffness>
        </dynamics>
      </axis>
    </joint>
    <link name='astribot_torso_link_4'>
      <pose relative_to='astribot_torso_joint_4'>0 0 0 0 -0 0</pose>
      <inertial>
        <pose>-0.008561 -0.004199 0.288559 0 -0 0</pose>
        <mass>8.0147</mass>
        <inertia>
          <ixx>0.0603684</ixx>
          <ixy>-0.000583001</ixy>
          <ixz>0.00307342</ixz>
          <iyy>0.0404615</iyy>
          <iyz>0.0023352</iyz>
          <izz>0.0447479</izz>
        </inertia>
      </inertial>
      <collision name='astribot_torso_link_4_collision'>
        <pose>0 0 0 0 -0 0</pose>
        <geometry>
          <mesh>
            <scale>1.2 1.2 1.2</scale>
            <uri>meshes/s1_torso/obj/astribot_torso_link_4_collision_mesh.obj</uri>
          </mesh>
        </geometry>
      </collision>
      <collision name='astribot_torso_link_4_collision_1'>
        <pose>0 0 0.56 0 -0 0</pose>
        <geometry>
          <sphere>
            <radius>0.23</radius>
          </sphere>
        </geometry>
      </collision>
      <visual name='astribot_torso_link_4_visual'>
        <pose>0 0 0 0 -0 0</pose>
        <geometry>
          <mesh>
            <scale>1 1 1</scale>
            <uri>meshes/s1_torso/obj/astribot_torso_link_4.obj</uri>
          </mesh>
        </geometry>
      </visual>
    </link>
    <joint name='astribot_arm_left_joint_1' type='revolute'>
      <pose relative_to='astribot_torso_link_4'>-0 0.150002 0.399354 -0 -1.22173 -1.5708</pose>
      <parent>astribot_torso_link_4</parent>
      <child>astribot_arm_left_link_1</child>
      <axis>
        <xyz>0 0 1</xyz>
        <limit>
          <lower>-3</lower>
          <upper>3</upper>
          <effort>265</effort>
          <velocity>8.4</velocity>
        </limit>
        <dynamics>
          <spring_reference>0</spring_reference>
          <spring_stiffness>0</spring_stiffness>
        </dynamics>
      </axis>
    </joint>
    <link name='astribot_arm_left_link_1'>
      <pose relative_to='astribot_arm_left_joint_1'>0 0 0 0 -0 0</pose>
      <inertial>
        <pose>0.00012 0.000475 -0.056826 0 -0 0</pose>
        <mass>0.599367</mass>
        <inertia>
          <ixx>0.00064791</ixx>
          <ixy>1.49e-06</ixy>
          <ixz>1.33e-06</ixz>
          <iyy>0.00065264</iyy>
          <iyz>1.6e-06</iyz>
          <izz>0.00050137</izz>
        </inertia>
      </inertial>
      <visual name='astribot_arm_left_link_1_visual'>
        <pose>0 0 0 0 -0 0</pose>
        <geometry>
          <mesh>
            <scale>1 1 1</scale>
            <uri>meshes/s1_arm/obj/astribot_arm_link_1.obj</uri>
          </mesh>
        </geometry>
      </visual>
    </link>
    <joint name='astribot_arm_left_joint_2' type='revolute'>
      <pose relative_to='astribot_arm_left_link_1'>0 0 0 1.5708 -0 0</pose>
      <parent>astribot_arm_left_link_1</parent>
      <child>astribot_arm_left_link_2</child>
      <axis>
        <xyz>0 0 1</xyz>
        <limit>
          <lower>-1.4</lower>
          <upper>0.4</upper>
          <effort>265</effort>
          <velocity>8.4</velocity>
        </limit>
        <dynamics>
          <spring_reference>0</spring_reference>
          <spring_stiffness>0</spring_stiffness>
        </dynamics>
      </axis>
    </joint>
    <link name='astribot_arm_left_link_2'>
      <pose relative_to='astribot_arm_left_joint_2'>0 0 0 0 -0 0</pose>
      <inertial>
        <pose>-0.003962 0.034907 0.042702 0 -0 0</pose>
        <mass>1.43695</mass>
        <inertia>
          <ixx>0.00360751</ixx>
          <ixy>-9.193e-05</ixy>
          <ixz>7.764e-05</ixz>
          <iyy>0.00283747</iyy>
          <iyz>0.00054945</iyz>
          <izz>0.00172927</izz>
        </inertia>
      </inertial>
      <visual name='astribot_arm_left_link_2_visual'>
        <pose>0 0 0 0 -0 0</pose>
        <geometry>
          <mesh>
            <scale>1 1 1</scale>
            <uri>meshes/s1_arm/obj/astribot_arm_left_link_2.obj</uri>
          </mesh>
        </geometry>
      </visual>
    </link>
    <joint name='astribot_arm_left_joint_3' type='revolute'>
      <pose relative_to='astribot_arm_left_link_2'>0 0.05 0 1.5708 0 -1.5708</pose>
      <parent>astribot_arm_left_link_2</parent>
      <child>astribot_arm_left_link_3</child>
      <axis>
        <xyz>0 0 1</xyz>
        <limit>
          <lower>-3</lower>
          <upper>1.4</upper>
          <effort>132</effort>
          <velocity>8.4</velocity>
        </limit>
        <dynamics>
          <spring_reference>0</spring_reference>
          <spring_stiffness>0</spring_stiffness>
        </dynamics>
      </axis>
    </joint>
    <link name='astribot_arm_left_link_3'>
      <pose relative_to='astribot_arm_left_joint_3'>0 0 0 0 -0 0</pose>
      <inertial>
        <pose>0.005313 0.000207 0.161367 0 -0 0</pose>
        <mass>2.09264</mass>
        <inertia>
          <ixx>0.0175218</ixx>
          <ixy>2.336e-05</ixy>
          <ixz>0.00144018</ixz>
          <iyy>0.0178467</iyy>
          <iyz>-3.027e-05</iyz>
          <izz>0.0021843</izz>
        </inertia>
      </inertial>
      <collision name='astribot_arm_left_link_3_collision'>
        <pose>0 0 0 0 -0 0</pose>
        <geometry>
          <mesh>
            <scale>1 1 1</scale>
            <uri>meshes/s1_arm/obj/astribot_arm_link_3_collision_mesh.obj</uri>
          </mesh>
        </geometry>
      </collision>
      <visual name='astribot_arm_left_link_3_visual'>
        <pose>0 0 0 0 -0 0</pose>
        <geometry>
          <mesh>
            <scale>1 1 1</scale>
            <uri>meshes/s1_arm/obj/astribot_arm_link_3.obj</uri>
          </mesh>
        </geometry>
      </visual>
    </link>
    <joint name='astribot_arm_left_joint_4' type='revolute'>
      <pose relative_to='astribot_arm_left_link_3'>0.03 0 0.309 -1.5708 0 0</pose>
      <parent>astribot_arm_left_link_3</parent>
      <child>astribot_arm_left_link_4</child>
      <axis>
        <xyz>0 0 1</xyz>
        <limit>
          <lower>0</lower>
          <upper>2.4</upper>
          <effort>142</effort>
          <velocity>15</velocity>
        </limit>
        <dynamics>
          <spring_reference>0</spring_reference>
          <spring_stiffness>0</spring_stiffness>
        </dynamics>
      </axis>
    </joint>
    <link name='astribot_arm_left_link_4'>
      <pose relative_to='astribot_arm_left_joint_4'>0 0 0 0 -0 0</pose>
      <inertial>
        <pose>0.000173 -0.012693 0.001961 0 -0 0</pose>
        <mass>0.365879</mass>
        <inertia>
          <ixx>0.00047693</ixx>
          <ixy>6.35e-06</ixy>
          <ixz>1.35e-06</ixz>
          <iyy>0.00036801</iyy>
          <iyz>7.05e-06</iyz>
          <izz>0.00050082</izz>
        </inertia>
      </inertial>
      <collision name='astribot_arm_left_link_4_collision'>
        <pose>0 0 0 0 -0 0</pose>
        <geometry>
          <mesh>
            <scale>1 1 1</scale>
            <uri>meshes/s1_arm/obj/astribot_arm_link_4_collision_mesh.obj</uri>
          </mesh>
        </geometry>
      </collision>
      <visual name='astribot_arm_left_link_4_visual'>
        <pose>0 0 0 0 -0 0</pose>
        <geometry>
          <mesh>
            <scale>1 1 1</scale>
            <uri>meshes/s1_arm/obj/astribot_arm_link_4.obj</uri>
          </mesh>
        </geometry>
      </visual>
    </link>
    <joint name='astribot_arm_left_joint_5' type='revolute'>
      <pose relative_to='astribot_arm_left_link_4'>0 0 0 1.5708 -0 0</pose>
      <parent>astribot_arm_left_link_4</parent>
      <child>astribot_arm_left_link_5</child>
      <axis>
        <xyz>0 0 1</xyz>
        <limit>
          <lower>-2</lower>
          <upper>2</upper>
          <effort>71</effort>
          <velocity>15</velocity>
        </limit>
        <dynamics>
          <spring_reference>0</spring_reference>
          <spring_stiffness>0</spring_stiffness>
        </dynamics>
      </axis>
    </joint>
    <link name='astribot_arm_left_link_5'>
      <pose relative_to='astribot_arm_left_joint_5'>0 0 0 0 -0 0</pose>
      <inertial>
        <pose>-0.00032 -0.000152 0.153704 0 -0 0</pose>
        <mass>1.24085</mass>
        <inertia>
          <ixx>0.00454092</ixx>
          <ixy>1.58e-06</ixy>
          <ixz>-5.91e-06</ixz>
          <iyy>0.00438922</iyy>
          <iyz>-4.927e-05</iyz>
          <izz>0.00079442</izz>
        </inertia>
      </inertial>
      <collision name='astribot_arm_left_link_5_collision'>
        <pose>0 0 0 0 -0 0</pose>
        <geometry>
          <mesh>
            <scale>1 1 1</scale>
            <uri>meshes/s1_arm/obj/astribot_arm_link_5_collision_mesh.obj</uri>
          </mesh>
        </geometry>
      </collision>
      <visual name='astribot_arm_left_link_5_visual'>
        <pose>0 0 0 0 -0 0</pose>
        <geometry>
          <mesh>
            <scale>1 1 1</scale>
            <uri>meshes/s1_arm/obj/astribot_arm_link_5.obj</uri>
          </mesh>
        </geometry>
      </visual>
    </link>
    <joint name='astribot_arm_left_joint_6' type='revolute'>
      <pose relative_to='astribot_arm_left_link_5'>0 0 0.277 -1.5708 0 0</pose>
      <parent>astribot_arm_left_link_5</parent>
      <child>astribot_arm_left_link_6</child>
      <axis>
        <xyz>0 0 1</xyz>
        <limit>
          <lower>-0.6</lower>
          <upper>0.6</upper>
          <effort>20</effort>
          <velocity>16.8</velocity>
        </limit>
        <dynamics>
          <spring_reference>0</spring_reference>
          <spring_stiffness>0</spring_stiffness>
        </dynamics>
      </axis>
    </joint>
    <link name='astribot_arm_left_link_6'>
      <pose relative_to='astribot_arm_left_joint_6'>0 0 0 0 -0 0</pose>
      <inertial>
        <pose>-0.000103 1.2e-05 0.000132 0 -0 0</pose>
        <mass>0.224653</mass>
        <inertia>
          <ixx>0.00016474</ixx>
          <ixy>7e-08</ixy>
          <ixz>2.5e-07</ixz>
          <iyy>0.00015608</iyy>
          <iyz>1.8e-07</iyz>
          <izz>8.555e-05</izz>
        </inertia>
      </inertial>
      <visual name='astribot_arm_left_link_6_visual'>
        <pose>0 0 0 0 -0 0</pose>
        <geometry>
          <mesh>
            <scale>1 1 1</scale>
            <uri>meshes/s1_arm/obj/astribot_arm_link_6.obj</uri>
          </mesh>
        </geometry>
      </visual>
    </link>
    <joint name='astribot_arm_left_joint_7' type='revolute'>
      <pose relative_to='astribot_arm_left_link_6'>0 0 0 3.14159 1.57079 3.14159</pose>
      <parent>astribot_arm_left_link_6</parent>
      <child>astribot_arm_left_link_7</child>
      <axis>
        <xyz>0 0 1</xyz>
        <limit>
          <lower>-1.4</lower>
          <upper>1.4</upper>
          <effort>20</effort>
          <velocity>16.8</velocity>
        </limit>
        <dynamics>
          <spring_reference>0</spring_reference>
          <spring_stiffness>0</spring_stiffness>
        </dynamics>
      </axis>
    </joint>
    <link name='astribot_arm_left_link_7'>
      <pose relative_to='astribot_arm_left_joint_7'>0 0 0 0 -0 0</pose>
      <inertial>
        <pose>0.004558 -0.068453 -0.000877 0 -0 0</pose>
        <mass>0.527722</mass>
        <inertia>
          <ixx>0.00177149</ixx>
          <ixy>4.67341e-05</ixy>
          <ixz>-2.32988e-06</ixz>
          <iyy>0.00111454</iyy>
          <iyz>2.49865e-05</iyz>
          <izz>0.00169552</izz>
        </inertia>
      </inertial>
      <collision name='astribot_arm_left_link_7_fixed_joint_lump__astribot_gripper_left_base_collision'>
        <pose>0.006 -0.048 0 1.5708 -0 0</pose>
        <geometry>
          <mesh>
            <scale>1 1 1</scale>
            <uri>meshes/s1_gripper/obj/astribot_gripper_base_link_collision_mesh.obj</uri>
          </mesh>
        </geometry>
      </collision>
      <visual name='astribot_arm_left_link_7_visual'>
        <pose>0 0 0 0 -0 0</pose>
        <geometry>
          <mesh>
            <scale>1 1 1</scale>
            <uri>meshes/s1_arm/obj/astribot_arm_link_7.obj</uri>
          </mesh>
        </geometry>
      </visual>
      <visual name='astribot_arm_left_link_7_fixed_joint_lump__astribot_gripper_left_base_visual_1'>
        <pose>0.006 -0.048 0 1.5708 -0 0</pose>
        <geometry>
          <mesh>
            <scale>1 1 1</scale>
            <uri>meshes/s1_gripper/obj/astribot_gripper_base_link.obj</uri>
          </mesh>
        </geometry>
      </visual>
    </link>
    <joint name='astribot_gripper_left_joint_L1' type='revolute'>
      <pose relative_to='astribot_arm_left_link_7'>0.019001 -0.1017 -0 1.5708 -0 0</pose>
      <parent>astribot_arm_left_link_7</parent>
      <child>astribot_gripper_left_Link_L1</child>
      <axis>
        <xyz>0 -1 0</xyz>
        <limit>
          <lower>0</lower>
          <upper>1.14</upper>
          <effort>1</effort>
          <velocity>1</velocity>
        </limit>
        <dynamics>
          <spring_reference>0</spring_reference>
          <spring_stiffness>0</spring_stiffness>
        </dynamics>
      </axis>
    </joint>
    <link name='astribot_gripper_left_Link_L1'>
      <pose relative_to='astribot_gripper_left_joint_L1'>0 0 0 0 -0 0</pose>
      <inertial>
        <pose>0 0 0.02 0 -0 0</pose>
        <mass>0.03</mass>
        <inertia>
          <ixx>0.001</ixx>
          <ixy>0</ixy>
          <ixz>0</ixz>
          <iyy>0.001</iyy>
          <iyz>0</iyz>
          <izz>0.001</izz>
        </inertia>
      </inertial>
      <visual name='astribot_gripper_left_Link_L1_visual'>
        <pose>0 0 0 0 -0 0</pose>
        <geometry>
          <mesh>
            <scale>1 1 1</scale>
            <uri>meshes/s1_gripper/obj/astribot_gripper_L1_Link.obj</uri>
          </mesh>
        </geometry>
      </visual>
    </link>
    <joint name='astribot_gripper_left_joint_L11' type='revolute'>
      <pose relative_to='astribot_gripper_left_Link_L1'>0.036 0 0.031749 0 -0.03 0</pose>
      <parent>astribot_gripper_left_Link_L1</parent>
      <child>astribot_gripper_left_Link_L11</child>
      <axis>
        <xyz>0 1 0</xyz>
        <limit>
          <lower>-3.14</lower>
          <upper>3.14</upper>
          <effort>1</effort>
          <velocity>1</velocity>
        </limit>
        <dynamics>
          <spring_reference>0</spring_reference>
          <spring_stiffness>0</spring_stiffness>
        </dynamics>
      </axis>
    </joint>
    <link name='astribot_gripper_left_Link_L11'>
      <pose relative_to='astribot_gripper_left_joint_L11'>0 0 0 0 -0 0</pose>
      <inertial>
        <pose>0 0 0.02 0 -0 0</pose>
        <mass>0.067</mass>
        <inertia>
          <ixx>0.001</ixx>
          <ixy>0</ixy>
          <ixz>0</ixz>
          <iyy>0.001</iyy>
          <iyz>0</iyz>
          <izz>0.001</izz>
        </inertia>
      </inertial>
      <collision name='astribot_gripper_left_Link_L11_collision'>
        <pose>0 0 0 0 -0 0</pose>
        <geometry>
          <mesh>
            <scale>1 1 1</scale>
            <uri>meshes/s1_gripper/obj/astribot_gripper_L11_Link_collision_mesh.obj</uri>
          </mesh>
        </geometry>
      </collision>
      <visual name='astribot_gripper_left_Link_L11_visual'>
        <pose>0 0 0 0 -0 0</pose>
        <geometry>
          <mesh>
            <scale>1 1 1</scale>
            <uri>meshes/s1_gripper/obj/astribot_gripper_L11_Link.obj</uri>
          </mesh>
        </geometry>
      </visual>
    </link>
    <joint name='astribot_gripper_left_joint_L2' type='revolute'>
      <pose relative_to='astribot_arm_left_link_7'>0.039 -0.1017 -0 1.5708 -0 0</pose>
      <parent>astribot_arm_left_link_7</parent>
      <child>astribot_gripper_left_Link_L2</child>
      <axis>
        <xyz>0 1 0</xyz>
        <limit>
          <lower>-3.14</lower>
          <upper>3.14</upper>
          <effort>1</effort>
          <velocity>1</velocity>
        </limit>
        <dynamics>
          <spring_reference>0</spring_reference>
          <spring_stiffness>0</spring_stiffness>
        </dynamics>
      </axis>
    </joint>
    <link name='astribot_gripper_left_Link_L2'>
      <pose relative_to='astribot_gripper_left_joint_L2'>0 0 0 0 -0 0</pose>
      <inertial>
        <pose>0 0 0.02 0 -0 0</pose>
        <mass>0.03</mass>
        <inertia>
          <ixx>0.001</ixx>
          <ixy>0</ixy>
          <ixz>0</ixz>
          <iyy>0.001</iyy>
          <iyz>0</iyz>
          <izz>0.001</izz>
        </inertia>
      </inertial>
      <collision name='astribot_gripper_left_Link_L2_collision'>
        <pose>0 0 0 0 -0 0</pose>
        <geometry>
          <mesh>
            <scale>1 1 1</scale>
            <uri>meshes/s1_gripper/obj/astribot_gripper_L2_Link_collision_mesh.obj</uri>
          </mesh>
        </geometry>
      </collision>
      <visual name='astribot_gripper_left_Link_L2_visual'>
        <pose>0 0 0 0 -0 0</pose>
        <geometry>
          <mesh>
            <scale>1 1 1</scale>
            <uri>meshes/s1_gripper/obj/astribot_gripper_L2_Link.obj</uri>
          </mesh>
        </geometry>
      </visual>
    </link>
    <joint name='astribot_gripper_left_joint_R1' type='revolute'>
      <pose relative_to='astribot_arm_left_link_7'>-0.007001 -0.1017 -0 1.5708 -0 0</pose>
      <parent>astribot_arm_left_link_7</parent>
      <child>astribot_gripper_left_Link_R1</child>
      <axis>
        <xyz>0 1 0</xyz>
        <limit>
          <lower>0</lower>
          <upper>1.14</upper>
          <effort>1</effort>
          <velocity>1</velocity>
        </limit>
        <dynamics>
          <spring_reference>0</spring_reference>
          <spring_stiffness>0</spring_stiffness>
        </dynamics>
      </axis>
    </joint>
    <link name='astribot_gripper_left_Link_R1'>
      <pose relative_to='astribot_gripper_left_joint_R1'>0 0 0 0 -0 0</pose>
      <inertial>
        <pose>0 0 0.02 0 -0 0</pose>
        <mass>0.03</mass>
        <inertia>
          <ixx>0.001</ixx>
          <ixy>0</ixy>
          <ixz>0</ixz>
          <iyy>0.001</iyy>
          <iyz>0</iyz>
          <izz>0.001</izz>
        </inertia>
      </inertial>
      <visual name='astribot_gripper_left_Link_R1_visual'>
        <pose>0 0 0 0 -0 0</pose>
        <geometry>
          <mesh>
            <scale>1 1 1</scale>
            <uri>meshes/s1_gripper/obj/astribot_gripper_R1_Link.obj</uri>
          </mesh>
        </geometry>
      </visual>
    </link>
    <joint name='astribot_gripper_left_joint_R11' type='revolute'>
      <pose relative_to='astribot_gripper_left_Link_R1'>-0.036 0 0.031749 0 0.03 0</pose>
      <parent>astribot_gripper_left_Link_R1</parent>
      <child>astribot_gripper_left_Link_R11</child>
      <axis>
        <xyz>0 1 0</xyz>
        <limit>
          <lower>-3.14</lower>
          <upper>3.14</upper>
          <effort>1</effort>
          <velocity>1</velocity>
        </limit>
        <dynamics>
          <spring_reference>0</spring_reference>
          <spring_stiffness>0</spring_stiffness>
        </dynamics>
      </axis>
    </joint>
    <link name='astribot_gripper_left_Link_R11'>
      <pose relative_to='astribot_gripper_left_joint_R11'>0 0 0 0 -0 0</pose>
      <inertial>
        <pose>0 0 0.02 0 -0 0</pose>
        <mass>0.067</mass>
        <inertia>
          <ixx>0.001</ixx>
          <ixy>0</ixy>
          <ixz>0</ixz>
          <iyy>0.001</iyy>
          <iyz>0</iyz>
          <izz>0.001</izz>
        </inertia>
      </inertial>
      <collision name='astribot_gripper_left_Link_R11_collision'>
        <pose>0 0 0 0 -0 0</pose>
        <geometry>
          <mesh>
            <scale>1 1 1</scale>
            <uri>meshes/s1_gripper/obj/astribot_gripper_R11_Link_collision_mesh.obj</uri>
          </mesh>
        </geometry>
      </collision>
      <visual name='astribot_gripper_left_Link_R11_visual'>
        <pose>0 0 0 0 -0 0</pose>
        <geometry>
          <mesh>
            <scale>1 1 1</scale>
            <uri>meshes/s1_gripper/obj/astribot_gripper_R11_Link.obj</uri>
          </mesh>
        </geometry>
      </visual>
    </link>
    <joint name='astribot_gripper_left_joint_R2' type='revolute'>
      <pose relative_to='astribot_arm_left_link_7'>-0.027 -0.1017 -0 1.5708 -0 0</pose>
      <parent>astribot_arm_left_link_7</parent>
      <child>astribot_gripper_left_Link_R2</child>
      <axis>
        <xyz>0 1 0</xyz>
        <limit>
          <lower>-3.14</lower>
          <upper>3.14</upper>
          <effort>1</effort>
          <velocity>1</velocity>
        </limit>
        <dynamics>
          <spring_reference>0</spring_reference>
          <spring_stiffness>0</spring_stiffness>
        </dynamics>
      </axis>
    </joint>
    <link name='astribot_gripper_left_Link_R2'>
      <pose relative_to='astribot_gripper_left_joint_R2'>0 0 0 0 -0 0</pose>
      <inertial>
        <pose>0 0 0.02 0 -0 0</pose>
        <mass>0.03</mass>
        <inertia>
          <ixx>0.001</ixx>
          <ixy>0</ixy>
          <ixz>0</ixz>
          <iyy>0.001</iyy>
          <iyz>0</iyz>
          <izz>0.001</izz>
        </inertia>
      </inertial>
      <collision name='astribot_gripper_left_Link_R2_collision'>
        <pose>0 0 0 0 -0 0</pose>
        <geometry>
          <mesh>
            <scale>1 1 1</scale>
            <uri>meshes/s1_gripper/obj/astribot_gripper_R2_Link_collision_mesh.obj</uri>
          </mesh>
        </geometry>
      </collision>
      <visual name='astribot_gripper_left_Link_R2_visual'>
        <pose>0 0 0 0 -0 0</pose>
        <geometry>
          <mesh>
            <scale>1 1 1</scale>
            <uri>meshes/s1_gripper/obj/astribot_gripper_R2_Link.obj</uri>
          </mesh>
        </geometry>
      </visual>
    </link>
    <joint name='astribot_arm_right_joint_1' type='revolute'>
      <pose relative_to='astribot_torso_link_4'>-0 -0.150002 0.399354 0 -1.22173 1.5708</pose>
      <parent>astribot_torso_link_4</parent>
      <child>astribot_arm_right_link_1</child>
      <axis>
        <xyz>0 0 1</xyz>
        <limit>
          <lower>-3</lower>
          <upper>3</upper>
          <effort>265</effort>
          <velocity>8.4</velocity>
        </limit>
        <dynamics>
          <spring_reference>0</spring_reference>
          <spring_stiffness>0</spring_stiffness>
        </dynamics>
      </axis>
    </joint>
    <link name='astribot_arm_right_link_1'>
      <pose relative_to='astribot_arm_right_joint_1'>0 0 0 0 -0 0</pose>
      <inertial>
        <pose>0.00012 0.000475 -0.056826 0 -0 0</pose>
        <mass>0.599367</mass>
        <inertia>
          <ixx>0.00064791</ixx>
          <ixy>1.49e-06</ixy>
          <ixz>1.33e-06</ixz>
          <iyy>0.00065264</iyy>
          <iyz>1.6e-06</iyz>
          <izz>0.00050137</izz>
        </inertia>
      </inertial>
      <visual name='astribot_arm_right_link_1_visual'>
        <pose>0 0 0 0 -0 0</pose>
        <geometry>
          <mesh>
            <scale>1 1 1</scale>
            <uri>meshes/s1_arm/obj/astribot_arm_link_1.obj</uri>
          </mesh>
        </geometry>
      </visual>
    </link>
    <joint name='astribot_arm_right_joint_2' type='revolute'>
      <pose relative_to='astribot_arm_right_link_1'>0 0 0 1.5708 -0 0</pose>
      <parent>astribot_arm_right_link_1</parent>
      <child>astribot_arm_right_link_2</child>
      <axis>
        <xyz>0 0 1</xyz>
        <limit>
          <lower>-1.4</lower>
          <upper>0.4</upper>
          <effort>265</effort>
          <velocity>8.4</velocity>
        </limit>
        <dynamics>
          <spring_reference>0</spring_reference>
          <spring_stiffness>0</spring_stiffness>
        </dynamics>
      </axis>
    </joint>
    <link name='astribot_arm_right_link_2'>
      <pose relative_to='astribot_arm_right_joint_2'>0 0 0 0 -0 0</pose>
      <inertial>
        <pose>-0.003847 0.035021 -0.040507 0 -0 0</pose>
        <mass>1.45811</mass>
        <inertia>
          <ixx>0.00394196</ixx>
          <ixy>-8.846e-05</ixy>
          <ixz>-3.742e-05</ixz>
          <iyy>0.00316298</iyy>
          <iyz>-0.0007079</iyz>
          <izz>0.00177295</izz>
        </inertia>
      </inertial>
      <visual name='astribot_arm_right_link_2_visual'>
        <pose>0 0 0 0 -0 0</pose>
        <geometry>
          <mesh>
            <scale>1 1 1</scale>
            <uri>meshes/s1_arm/obj/astribot_arm_right_link_2.obj</uri>
          </mesh>
        </geometry>
      </visual>
    </link>
    <joint name='astribot_arm_right_joint_3' type='revolute'>
      <pose relative_to='astribot_arm_right_link_2'>0 0.05 0 1.5708 0 -1.5708</pose>
      <parent>astribot_arm_right_link_2</parent>
      <child>astribot_arm_right_link_3</child>
      <axis>
        <xyz>0 0 1</xyz>
        <limit>
          <lower>-1.4</lower>
          <upper>3</upper>
          <effort>132</effort>
          <velocity>8.4</velocity>
        </limit>
        <dynamics>
          <spring_reference>0</spring_reference>
          <spring_stiffness>0</spring_stiffness>
        </dynamics>
      </axis>
    </joint>
    <link name='astribot_arm_right_link_3'>
      <pose relative_to='astribot_arm_right_joint_3'>0 0 0 0 -0 0</pose>
      <inertial>
        <pose>0.005313 0.000207 0.161367 0 -0 0</pose>
        <mass>2.09264</mass>
        <inertia>
          <ixx>0.0175218</ixx>
          <ixy>2.336e-05</ixy>
          <ixz>0.00144018</ixz>
          <iyy>0.0178467</iyy>
          <iyz>-3.027e-05</iyz>
          <izz>0.0021843</izz>
        </inertia>
      </inertial>
      <collision name='astribot_arm_right_link_3_collision'>
        <pose>0 0 0 0 -0 0</pose>
        <geometry>
          <mesh>
            <scale>1 1 1</scale>
            <uri>meshes/s1_arm/obj/astribot_arm_link_3_collision_mesh.obj</uri>
          </mesh>
        </geometry>
      </collision>
      <visual name='astribot_arm_right_link_3_visual'>
        <pose>0 0 0 0 -0 0</pose>
        <geometry>
          <mesh>
            <scale>1 1 1</scale>
            <uri>meshes/s1_arm/obj/astribot_arm_link_3.obj</uri>
          </mesh>
        </geometry>
      </visual>
    </link>
    <joint name='astribot_arm_right_joint_4' type='revolute'>
      <pose relative_to='astribot_arm_right_link_3'>0.03 0 0.309 -1.5708 0 0</pose>
      <parent>astribot_arm_right_link_3</parent>
      <child>astribot_arm_right_link_4</child>
      <axis>
        <xyz>0 0 1</xyz>
        <limit>
          <lower>0</lower>
          <upper>2.4</upper>
          <effort>142</effort>
          <velocity>15</velocity>
        </limit>
        <dynamics>
          <spring_reference>0</spring_reference>
          <spring_stiffness>0</spring_stiffness>
        </dynamics>
      </axis>
    </joint>
    <link name='astribot_arm_right_link_4'>
      <pose relative_to='astribot_arm_right_joint_4'>0 0 0 0 -0 0</pose>
      <inertial>
        <pose>0.000173 -0.012693 0.001961 0 -0 0</pose>
        <mass>0.365879</mass>
        <inertia>
          <ixx>0.00047693</ixx>
          <ixy>6.35e-06</ixy>
          <ixz>1.35e-06</ixz>
          <iyy>0.00036801</iyy>
          <iyz>7.05e-06</iyz>
          <izz>0.00050082</izz>
        </inertia>
      </inertial>
      <collision name='astribot_arm_right_link_4_collision'>
        <pose>0 0 0 0 -0 0</pose>
        <geometry>
          <mesh>
            <scale>1 1 1</scale>
            <uri>meshes/s1_arm/obj/astribot_arm_link_4_collision_mesh.obj</uri>
          </mesh>
        </geometry>
      </collision>
      <visual name='astribot_arm_right_link_4_visual'>
        <pose>0 0 0 0 -0 0</pose>
        <geometry>
          <mesh>
            <scale>1 1 1</scale>
            <uri>meshes/s1_arm/obj/astribot_arm_link_4.obj</uri>
          </mesh>
        </geometry>
      </visual>
    </link>
    <joint name='astribot_arm_right_joint_5' type='revolute'>
      <pose relative_to='astribot_arm_right_link_4'>0 0 0 1.5708 -0 0</pose>
      <parent>astribot_arm_right_link_4</parent>
      <child>astribot_arm_right_link_5</child>
      <axis>
        <xyz>0 0 1</xyz>
        <limit>
          <lower>-2</lower>
          <upper>2</upper>
          <effort>71</effort>
          <velocity>15</velocity>
        </limit>
        <dynamics>
          <spring_reference>0</spring_reference>
          <spring_stiffness>0</spring_stiffness>
        </dynamics>
      </axis>
    </joint>
    <link name='astribot_arm_right_link_5'>
      <pose relative_to='astribot_arm_right_joint_5'>0 0 0 0 -0 0</pose>
      <inertial>
        <pose>-0.00032 -0.000152 0.153704 0 -0 0</pose>
        <mass>1.24085</mass>
        <inertia>
          <ixx>0.00454092</ixx>
          <ixy>1.58e-06</ixy>
          <ixz>-5.91e-06</ixz>
          <iyy>0.00438922</iyy>
          <iyz>-4.927e-05</iyz>
          <izz>0.00079442</izz>
        </inertia>
      </inertial>
      <collision name='astribot_arm_right_link_5_collision'>
        <pose>0 0 0 0 -0 0</pose>
        <geometry>
          <mesh>
            <scale>1 1 1</scale>
            <uri>meshes/s1_arm/obj/astribot_arm_link_5_collision_mesh.obj</uri>
          </mesh>
        </geometry>
      </collision>
      <visual name='astribot_arm_right_link_5_visual'>
        <pose>0 0 0 0 -0 0</pose>
        <geometry>
          <mesh>
            <scale>1 1 1</scale>
            <uri>meshes/s1_arm/obj/astribot_arm_link_5.obj</uri>
          </mesh>
        </geometry>
      </visual>
    </link>
    <joint name='astribot_arm_right_joint_6' type='revolute'>
      <pose relative_to='astribot_arm_right_link_5'>0 0 0.277 -1.5708 0 0</pose>
      <parent>astribot_arm_right_link_5</parent>
      <child>astribot_arm_right_link_6</child>
      <axis>
        <xyz>0 0 1</xyz>
        <limit>
          <lower>-0.6</lower>
          <upper>0.6</upper>
          <effort>20</effort>
          <velocity>16.8</velocity>
        </limit>
        <dynamics>
          <spring_reference>0</spring_reference>
          <spring_stiffness>0</spring_stiffness>
        </dynamics>
      </axis>
    </joint>
    <link name='astribot_arm_right_link_6'>
      <pose relative_to='astribot_arm_right_joint_6'>0 0 0 0 -0 0</pose>
      <inertial>
        <pose>-0.000103 1.2e-05 0.000132 0 -0 0</pose>
        <mass>0.224653</mass>
        <inertia>
          <ixx>0.00016474</ixx>
          <ixy>7e-08</ixy>
          <ixz>2.5e-07</ixz>
          <iyy>0.00015608</iyy>
          <iyz>1.8e-07</iyz>
          <izz>8.555e-05</izz>
        </inertia>
      </inertial>
      <visual name='astribot_arm_right_link_6_visual'>
        <pose>0 0 0 0 -0 0</pose>
        <geometry>
          <mesh>
            <scale>1 1 1</scale>
            <uri>meshes/s1_arm/obj/astribot_arm_link_6.obj</uri>
          </mesh>
        </geometry>
      </visual>
    </link>
    <joint name='astribot_arm_right_joint_7' type='revolute'>
      <pose relative_to='astribot_arm_right_link_6'>0 0 0 3.14159 1.57079 3.14159</pose>
      <parent>astribot_arm_right_link_6</parent>
      <child>astribot_arm_right_link_7</child>
      <axis>
        <xyz>0 0 1</xyz>
        <limit>
          <lower>-1.4</lower>
          <upper>1.4</upper>
          <effort>20</effort>
          <velocity>16.8</velocity>
        </limit>
        <dynamics>
          <spring_reference>0</spring_reference>
          <spring_stiffness>0</spring_stiffness>
        </dynamics>
      </axis>
    </joint>
    <link name='astribot_arm_right_link_7'>
      <pose relative_to='astribot_arm_right_joint_7'>0 0 0 0 -0 0</pose>
      <inertial>
        <pose>0.004558 -0.068453 -0.000877 0 -0 0</pose>
        <mass>0.527722</mass>
        <inertia>
          <ixx>0.00177149</ixx>
          <ixy>4.67341e-05</ixy>
          <ixz>-2.32988e-06</ixz>
          <iyy>0.00111454</iyy>
          <iyz>2.49865e-05</iyz>
          <izz>0.00169552</izz>
        </inertia>
      </inertial>
      <collision name='astribot_arm_right_link_7_fixed_joint_lump__astribot_gripper_right_base_collision'>
        <pose>0.006 -0.048 0 1.5708 -0 0</pose>
        <geometry>
          <mesh>
            <scale>1 1 1</scale>
            <uri>meshes/s1_gripper/obj/astribot_gripper_base_link_collision_mesh.obj</uri>
          </mesh>
        </geometry>
      </collision>
      <visual name='astribot_arm_right_link_7_visual'>
        <pose>0 0 0 0 -0 0</pose>
        <geometry>
          <mesh>
            <scale>1 1 1</scale>
            <uri>meshes/s1_arm/obj/astribot_arm_link_7.obj</uri>
          </mesh>
        </geometry>
      </visual>
      <visual name='astribot_arm_right_link_7_fixed_joint_lump__astribot_gripper_right_base_visual_1'>
        <pose>0.006 -0.048 0 1.5708 -0 0</pose>
        <geometry>
          <mesh>
            <scale>1 1 1</scale>
            <uri>meshes/s1_gripper/obj/astribot_gripper_base_link.obj</uri>
          </mesh>
        </geometry>
      </visual>
    </link>
    <joint name='astribot_gripper_right_joint_L1' type='revolute'>
      <pose relative_to='astribot_arm_right_link_7'>0.019001 -0.1017 -0 1.5708 -0 0</pose>
      <parent>astribot_arm_right_link_7</parent>
      <child>astribot_gripper_right_Link_L1</child>
      <axis>
        <xyz>0 -1 0</xyz>
        <limit>
          <lower>0</lower>
          <upper>1.14</upper>
          <effort>1</effort>
          <velocity>1</velocity>
        </limit>
        <dynamics>
          <spring_reference>0</spring_reference>
          <spring_stiffness>0</spring_stiffness>
        </dynamics>
      </axis>
    </joint>
    <link name='astribot_gripper_right_Link_L1'>
      <pose relative_to='astribot_gripper_right_joint_L1'>0 0 0 0 -0 0</pose>
      <inertial>
        <pose>0 0 0.02 0 -0 0</pose>
        <mass>0.03</mass>
        <inertia>
          <ixx>0.001</ixx>
          <ixy>0</ixy>
          <ixz>0</ixz>
          <iyy>0.001</iyy>
          <iyz>0</iyz>
          <izz>0.001</izz>
        </inertia>
      </inertial>
      <visual name='astribot_gripper_right_Link_L1_visual'>
        <pose>0 0 0 0 -0 0</pose>
        <geometry>
          <mesh>
            <scale>1 1 1</scale>
            <uri>meshes/s1_gripper/obj/astribot_gripper_L1_Link.obj</uri>
          </mesh>
        </geometry>
      </visual>
    </link>
    <joint name='astribot_gripper_right_joint_L11' type='revolute'>
      <pose relative_to='astribot_gripper_right_Link_L1'>0.036 0 0.031749 0 -0.03 0</pose>
      <parent>astribot_gripper_right_Link_L1</parent>
      <child>astribot_gripper_right_Link_L11</child>
      <axis>
        <xyz>0 1 0</xyz>
        <limit>
          <lower>-3.14</lower>
          <upper>3.14</upper>
          <effort>1</effort>
          <velocity>1</velocity>
        </limit>
        <dynamics>
          <spring_reference>0</spring_reference>
          <spring_stiffness>0</spring_stiffness>
        </dynamics>
      </axis>
    </joint>
    <link name='astribot_gripper_right_Link_L11'>
      <pose relative_to='astribot_gripper_right_joint_L11'>0 0 0 0 -0 0</pose>
      <inertial>
        <pose>0 0 0.02 0 -0 0</pose>
        <mass>0.067</mass>
        <inertia>
          <ixx>0.001</ixx>
          <ixy>0</ixy>
          <ixz>0</ixz>
          <iyy>0.001</iyy>
          <iyz>0</iyz>
          <izz>0.001</izz>
        </inertia>
      </inertial>
      <collision name='astribot_gripper_right_Link_L11_collision'>
        <pose>0 0 0 0 -0 0</pose>
        <geometry>
          <mesh>
            <scale>1 1 1</scale>
            <uri>meshes/s1_gripper/obj/astribot_gripper_L11_Link_collision_mesh.obj</uri>
          </mesh>
        </geometry>
      </collision>
      <visual name='astribot_gripper_right_Link_L11_visual'>
        <pose>0 0 0 0 -0 0</pose>
        <geometry>
          <mesh>
            <scale>1 1 1</scale>
            <uri>meshes/s1_gripper/obj/astribot_gripper_L11_Link.obj</uri>
          </mesh>
        </geometry>
      </visual>
    </link>
    <joint name='astribot_gripper_right_joint_L2' type='revolute'>
      <pose relative_to='astribot_arm_right_link_7'>0.039 -0.1017 -0 1.5708 -0 0</pose>
      <parent>astribot_arm_right_link_7</parent>
      <child>astribot_gripper_right_Link_L2</child>
      <axis>
        <xyz>0 1 0</xyz>
        <limit>
          <lower>-3.14</lower>
          <upper>3.14</upper>
          <effort>1</effort>
          <velocity>1</velocity>
        </limit>
        <dynamics>
          <spring_reference>0</spring_reference>
          <spring_stiffness>0</spring_stiffness>
        </dynamics>
      </axis>
    </joint>
    <link name='astribot_gripper_right_Link_L2'>
      <pose relative_to='astribot_gripper_right_joint_L2'>0 0 0 0 -0 0</pose>
      <inertial>
        <pose>0 0 0.02 0 -0 0</pose>
        <mass>0.03</mass>
        <inertia>
          <ixx>0.001</ixx>
          <ixy>0</ixy>
          <ixz>0</ixz>
          <iyy>0.001</iyy>
          <iyz>0</iyz>
          <izz>0.001</izz>
        </inertia>
      </inertial>
      <collision name='astribot_gripper_right_Link_L2_collision'>
        <pose>0 0 0 0 -0 0</pose>
        <geometry>
          <mesh>
            <scale>1 1 1</scale>
            <uri>meshes/s1_gripper/obj/astribot_gripper_L2_Link_collision_mesh.obj</uri>
          </mesh>
        </geometry>
      </collision>
      <visual name='astribot_gripper_right_Link_L2_visual'>
        <pose>0 0 0 0 -0 0</pose>
        <geometry>
          <mesh>
            <scale>1 1 1</scale>
            <uri>meshes/s1_gripper/obj/astribot_gripper_L2_Link.obj</uri>
          </mesh>
        </geometry>
      </visual>
    </link>
    <joint name='astribot_gripper_right_joint_R1' type='revolute'>
      <pose relative_to='astribot_arm_right_link_7'>-0.007001 -0.1017 -0 1.5708 -0 0</pose>
      <parent>astribot_arm_right_link_7</parent>
      <child>astribot_gripper_right_Link_R1</child>
      <axis>
        <xyz>0 1 0</xyz>
        <limit>
          <lower>0</lower>
          <upper>1.14</upper>
          <effort>1</effort>
          <velocity>1</velocity>
        </limit>
        <dynamics>
          <spring_reference>0</spring_reference>
          <spring_stiffness>0</spring_stiffness>
        </dynamics>
      </axis>
    </joint>
    <link name='astribot_gripper_right_Link_R1'>
      <pose relative_to='astribot_gripper_right_joint_R1'>0 0 0 0 -0 0</pose>
      <inertial>
        <pose>0 0 0.02 0 -0 0</pose>
        <mass>0.03</mass>
        <inertia>
          <ixx>0.001</ixx>
          <ixy>0</ixy>
          <ixz>0</ixz>
          <iyy>0.001</iyy>
          <iyz>0</iyz>
          <izz>0.001</izz>
        </inertia>
      </inertial>
      <visual name='astribot_gripper_right_Link_R1_visual'>
        <pose>0 0 0 0 -0 0</pose>
        <geometry>
          <mesh>
            <scale>1 1 1</scale>
            <uri>meshes/s1_gripper/obj/astribot_gripper_R1_Link.obj</uri>
          </mesh>
        </geometry>
      </visual>
    </link>
    <joint name='astribot_gripper_right_joint_R11' type='revolute'>
      <pose relative_to='astribot_gripper_right_Link_R1'>-0.036 0 0.031749 0 0.03 0</pose>
      <parent>astribot_gripper_right_Link_R1</parent>
      <child>astribot_gripper_right_Link_R11</child>
      <axis>
        <xyz>0 1 0</xyz>
        <limit>
          <lower>-3.14</lower>
          <upper>3.14</upper>
          <effort>1</effort>
          <velocity>1</velocity>
        </limit>
        <dynamics>
          <spring_reference>0</spring_reference>
          <spring_stiffness>0</spring_stiffness>
        </dynamics>
      </axis>
    </joint>
    <link name='astribot_gripper_right_Link_R11'>
      <pose relative_to='astribot_gripper_right_joint_R11'>0 0 0 0 -0 0</pose>
      <inertial>
        <pose>0 0 0.02 0 -0 0</pose>
        <mass>0.067</mass>
        <inertia>
          <ixx>0.001</ixx>
          <ixy>0</ixy>
          <ixz>0</ixz>
          <iyy>0.001</iyy>
          <iyz>0</iyz>
          <izz>0.001</izz>
        </inertia>
      </inertial>
      <collision name='astribot_gripper_right_Link_R11_collision'>
        <pose>0 0 0 0 -0 0</pose>
        <geometry>
          <mesh>
            <scale>1 1 1</scale>
            <uri>meshes/s1_gripper/obj/astribot_gripper_R11_Link_collision_mesh.obj</uri>
          </mesh>
        </geometry>
      </collision>
      <visual name='astribot_gripper_right_Link_R11_visual'>
        <pose>0 0 0 0 -0 0</pose>
        <geometry>
          <mesh>
            <scale>1 1 1</scale>
            <uri>meshes/s1_gripper/obj/astribot_gripper_R11_Link.obj</uri>
          </mesh>
        </geometry>
      </visual>
    </link>
    <joint name='astribot_gripper_right_joint_R2' type='revolute'>
      <pose relative_to='astribot_arm_right_link_7'>-0.027 -0.1017 -0 1.5708 -0 0</pose>
      <parent>astribot_arm_right_link_7</parent>
      <child>astribot_gripper_right_Link_R2</child>
      <axis>
        <xyz>0 1 0</xyz>
        <limit>
          <lower>-3.14</lower>
          <upper>3.14</upper>
          <effort>1</effort>
          <velocity>1</velocity>
        </limit>
        <dynamics>
          <spring_reference>0</spring_reference>
          <spring_stiffness>0</spring_stiffness>
        </dynamics>
      </axis>
    </joint>
    <link name='astribot_gripper_right_Link_R2'>
      <pose relative_to='astribot_gripper_right_joint_R2'>0 0 0 0 -0 0</pose>
      <inertial>
        <pose>0 0 0.02 0 -0 0</pose>
        <mass>0.03</mass>
        <inertia>
          <ixx>0.001</ixx>
          <ixy>0</ixy>
          <ixz>0</ixz>
          <iyy>0.001</iyy>
          <iyz>0</iyz>
          <izz>0.001</izz>
        </inertia>
      </inertial>
      <collision name='astribot_gripper_right_Link_R2_collision'>
        <pose>0 0 0 0 -0 0</pose>
        <geometry>
          <mesh>
            <scale>1 1 1</scale>
            <uri>meshes/s1_gripper/obj/astribot_gripper_R2_Link_collision_mesh.obj</uri>
          </mesh>
        </geometry>
      </collision>
      <visual name='astribot_gripper_right_Link_R2_visual'>
        <pose>0 0 0 0 -0 0</pose>
        <geometry>
          <mesh>
            <scale>1 1 1</scale>
            <uri>meshes/s1_gripper/obj/astribot_gripper_R2_Link.obj</uri>
          </mesh>
        </geometry>
      </visual>
    </link>
  </model>
</sdf>
