<?xml version="1.0" ?>
<!-- =================================================================================== -->
<!-- |    This document was autogenerated by xacro from astribot_s1_head.xacro         | -->
<!-- |    EDITING THIS FILE BY HAND IS NOT RECOMMENDED                                 | -->
<!-- =================================================================================== -->
<!-- This URDF was automatically created by SolidWorks to URDF Exporter! Originally created by Stephen Brawner (brawner@gmail.com) 
     Commit Version: 1.6.0-4-g7f85cfe  Build Version: 1.6.7995.38578
     For more information, please see http://wiki.ros.org/sw_urdf_exporter -->
<robot name="astribot_head">
  <link name="astribot_head_base_link">
    <inertial>
      <origin rpy="0 0 0" xyz="-0.02816247 -0.00023176 -0.05211965"/>
      <mass value="0.39541440"/>
      <inertia ixx="0.00036025" ixy="-0.00003505" ixz="0.00004865" iyy="0.00049377" iyz="0.00000243" izz="0.00074441"/>
    </inertial>
  </link>
  <link name="astribot_head_link_1">
    <inertial>
      <origin rpy="0 0 0" xyz="0.00003191 -0.00038566 -0.02579910"/>
      <mass value="0.13910581"/>
      <inertia ixx="0.00004567" ixy="0.00000003" ixz="0.00000004" iyy="0.00004789" iyz="-0.00000091" izz="0.00003779"/>
    </inertial>
  </link>
  <joint name="astribot_head_joint_1" type="revolute">
    <origin rpy="0 0 0" xyz="0 0 0"/>
    <parent link="astribot_head_base_link"/>
    <child link="astribot_head_link_1"/>
    <axis xyz="0 0 1"/>
    <limit effort="100" lower="-1.57" upper="1.57" velocity="4.0"/>
  </joint>
  <link name="astribot_head_link_2">
    <inertial>
      <origin rpy="0 0 0" xyz="0.00705824 -0.14472601 -0.00061724"/>
      <mass value="0.97012447"/>
      <inertia ixx="0.00555660" ixy="-0.00041600" ixz="-0.00000036" iyy="0.00151908" iyz="-0.00012043" izz="0.00544493"/>
    </inertial>
    <collision>
      <origin xyz="0 -0.15 0" rpy="0 0 0"/>
      <geometry>
        <sphere radius="0.11"/>
      </geometry>
    </collision>
  </link>
  <joint name="astribot_head_joint_2" type="revolute">
    <origin rpy="-1.5708 0 0" xyz="0 0 0"/>
    <parent link="astribot_head_link_1"/>
    <child link="astribot_head_link_2"/>
    <axis xyz="0 0 1"/>
    <limit effort="100" lower="-1.22" upper="1.22" velocity="4.0"/>
  </joint>
</robot>
