<?xml version="1.0"?>
<sdf version='1.7'>
  <model name='astribot_torso'>
    <link name="base">
     <inertial>
      <mass>0.0</mass>
       <inertia>
        <ixx>0</ixx>
        <ixy>0</ixy>
        <ixz>0</ixz>
        <iyy>0</iyy>
        <iyz>0</iyz>
        <izz>0</izz>
      </inertia>
     </inertial>
    </link>
    <!--joint between {parent} and link_0-->
    <joint name="base_joint" type="fixed">
      <child>astribot_torso_base</child>
      <parent>base</parent>
    </joint>
    <link name='astribot_torso_base'>
      <inertial>
        <pose>-0.062784 0.007017 0.035375 0 0 0</pose>
        <mass>39.24781</mass>
        <inertia>
          <ixx>1.071997</ixx>
          <ixy>0.015889</ixy>
          <ixz>-0.058447</ixz>
          <iyy>1.218431</iyy>
          <iyz>-0.002015</iyz>
          <izz>1.489411</izz>
        </inertia>
      </inertial>
      <collision name='astribot_torso_base_collision'>
        <pose>0 0 -0.05 0 -0 0</pose>
        <geometry>
          <cylinder>
            <length>0.1</length>
            <radius>0.3</radius>
          </cylinder>
        </geometry>
      </collision>
    </link>
    <joint name='astribot_torso_joint_1' type='revolute'>
      <pose relative_to='astribot_torso_base'>0 0 0.12 1.57079 1.57079 -3.14159</pose>
      <parent>astribot_torso_base</parent>
      <child>astribot_torso_link_1</child>
      <axis>
        <xyz>0 0 1</xyz>
        <limit>
          <lower>-0.04</lower>
          <upper>1.3</upper>
          <effort>100</effort>
          <velocity>1.8</velocity>
        </limit>
        <dynamics>
          <spring_reference>0</spring_reference>
          <spring_stiffness>0</spring_stiffness>
        </dynamics>
      </axis>
    </joint>
    <link name='astribot_torso_link_1'>
      <pose relative_to='astribot_torso_joint_1'>0 0 0 0 -0 0</pose>
      <inertial>
        <pose>-0.15249 0.000211 -0.003348 0 -0 0</pose>
        <mass>7.3766</mass>
        <inertia>
          <ixx>0.028834</ixx>
          <ixy>-0.0052759</ixy>
          <ixz>0.00010767</ixz>
          <iyy>0.1483</iyy>
          <iyz>1.1652e-05</iyz>
          <izz>0.14268</izz>
        </inertia>
      </inertial>
      <collision name='astribot_torso_link_1_collision'>
        <pose>-0.15 0 0 0 1.5708 0</pose>
        <geometry>
          <capsule>
            <length>0.3</length>
            <radius>0.1</radius>
          </capsule>
        </geometry>
      </collision>
    </link>
    <joint name='astribot_torso_joint_2' type='revolute'>
      <pose relative_to='astribot_torso_link_1'>-0.38 0 0 0 -0 0</pose>
      <parent>astribot_torso_link_1</parent>
      <child>astribot_torso_link_2</child>
      <axis>
        <xyz>0 0 1</xyz>
        <limit>
          <lower>-2.3</lower>
          <upper>0.06</upper>
          <effort>100</effort>
          <velocity>1.8</velocity>
        </limit>
        <dynamics>
          <spring_reference>0</spring_reference>
          <spring_stiffness>0</spring_stiffness>
        </dynamics>
      </axis>
    </joint>
    <link name='astribot_torso_link_2'>
      <pose relative_to='astribot_torso_joint_2'>0 0 0 0 -0 0</pose>
      <inertial>
        <pose>-0.22214 0.028873 0.00059 0 -0 0</pose>
        <mass>5.6183</mass>
        <inertia>
          <ixx>0.0082545</ixx>
          <ixy>0.0011523</ixy>
          <ixz>0.00035614</ixz>
          <iyy>0.012677</iyy>
          <iyz>-5.8287e-05</iyz>
          <izz>0.017512</izz>
        </inertia>
      </inertial>
      <collision name='astribot_torso_link_2_collision'>
        <pose>-0.15 0.03 0 0.25 1.5708 0</pose>
        <geometry>
          <capsule>
            <length>0.3</length>
            <radius>0.1</radius>
          </capsule>
        </geometry>
      </collision>
    </link>
    <joint name='astribot_torso_joint_3' type='revolute'>
      <pose relative_to='astribot_torso_link_2'>-0.39 0 0 0 -0 0</pose>
      <parent>astribot_torso_link_2</parent>
      <child>astribot_torso_link_3</child>
      <axis>
        <xyz>0 0 1</xyz>
        <limit>
          <lower>-0.4</lower>
          <upper>2.3</upper>
          <effort>100</effort>
          <velocity>1.8</velocity>
        </limit>
        <dynamics>
          <spring_reference>0</spring_reference>
          <spring_stiffness>0</spring_stiffness>
        </dynamics>
      </axis>
    </joint>
    <link name='astribot_torso_link_3'>
      <pose relative_to='astribot_torso_joint_3'>0 0 0 0 -0 0</pose>
      <inertial>
        <pose>-0.017519 0.000595 0.000258 0 -0 0</pose>
        <mass>0.49013</mass>
        <inertia>
          <ixx>0.00022212</ixx>
          <ixy>-2.6767e-07</ixy>
          <ixz>4.3987e-07</ixz>
          <iyy>0.00036522</iyy>
          <iyz>3.8834e-07</iyz>
          <izz>0.00038039</izz>
        </inertia>
      </inertial>
      <collision name='astribot_torso_link_3_collision'>
        <pose>-0.18 0.01 0 0 1.5708 0</pose>
        <geometry>
          <capsule>
            <length>0.35</length>
            <radius>0.09</radius>
          </capsule>
        </geometry>
      </collision>
    </link>
    <joint name='astribot_torso_joint_4' type='revolute'>
      <pose relative_to='astribot_torso_link_3'>0 0 0 1.5708 0 -1.5708</pose>
      <parent>astribot_torso_link_3</parent>
      <child>astribot_torso_link_4</child>
      <axis>
        <xyz>0 0 1</xyz>
        <limit>
          <lower>-1.2</lower>
          <upper>1.2</upper>
          <effort>100</effort>
          <velocity>1.8</velocity>
        </limit>
        <dynamics>
          <spring_reference>0</spring_reference>
          <spring_stiffness>0</spring_stiffness>
        </dynamics>
      </axis>
    </joint>
    <link name='astribot_torso_link_4'>
      <pose relative_to='astribot_torso_joint_4'>0 0 0 0 -0 0</pose>
      <inertial>
        <pose>0.004762 -4.6e-05 0.242913 0 -0 0</pose>
        <mass>3.55696</mass>
        <inertia>
          <ixx>0.0165768</ixx>
          <ixy>-9.94098e-06</ixy>
          <ixz>-0.000100011</ixz>
          <iyy>0.0149044</iyy>
          <iyz>9.86752e-07</iyz>
          <izz>0.0110629</izz>
        </inertia>
      </inertial>
    </link>
  </model>
</sdf>
